<?xml version="1.0" ?>


<robot name="xela_allegro_hand">

  <!-- colors -->
  <material name="blue">
    <color rgba="0.0 0.0 0.8 1.0"/>
  </material>
  <material name="green">
    <color rgba="0.0 0.8 0.0 1.0"/>
  </material>
  <material name="yellow">
    <color rgba="0.8 0.8 0.0 1.0"/>
  </material>
  <material name="orange">
    <color rgba="1.0 0.4 0.04 1.0"/>
  </material>
  <material name="red">
    <color rgba="0.8 0 0 1.0"/>
  </material>


  <!--PALM-->

  <link name="allegro_base_link" >
    <visual>
     <origin rpy="0 3.14159265359 1.57079632679 " xyz="-0.0265 0 -0.0964"/>
     <geometry>
       <mesh filename="package://xela_models/mesh_simplified/palm.obj" scale="0.001 0.001 0.001"/>
     </geometry>
     <material name="blue"/>
    </visual>
    <inertial>
      <mass value="0.4288"/>
      <origin rpy="0 0 0" xyz="0 0 0"/>
      <inertia ixx="2.04e-03" ixy="8.58e-06" ixz="8.58e-06" iyy="1.23e-03" iyz="0.0" izz="1.25e-03"/>
    </inertial>

    <!-- Collision geometry - copy from visual -->
    <collision>
      <origin rpy="0 3.14159265359 1.57079632679 " xyz="-0.0265 0 -0.0964"/>
      <geometry>
        <mesh filename="package://xela_models/mesh_simplified/palm.obj" scale="0.001 0.001 0.001"/>
      </geometry>
    </collision>
  </link>

  <!-- palm sensor 1 (top-right) -->
  <link name="palm_sensor_1_link">
    <visual>
      <origin rpy="0 0 0 " xyz="0.0195 0.0228 -0.022"/>
      <geometry>
        <box size="0.001 0.0405 0.026"/>
      </geometry>
    </visual>
    <inertial>
      <mass value="0"/>
      <origin rpy="0 0 0" xyz="0 0 0"/>
      <inertia ixx="0" ixy="0" ixz="0" iyy="0" iyz="0" izz="0"/>
    </inertial>
    <collision>
      <origin rpy="0 0 0 " xyz="0.0195 0.0228 -0.022"/>
      <geometry>
        <box size="0.001 0.0405 0.026"/>
      </geometry>
    </collision>
  </link>
  <joint name="palm_sensor_1_joint" type="fixed">
    <parent link="allegro_base_link"/>
    <child link="palm_sensor_1_link"/>
    <origin xyz="0 0 0" rpy="0 0 0" />
  </joint>

  <!-- palm sensor 2 (top-left) -->
  <link name="palm_sensor_2_link">
    <visual>
      <origin rpy="0 0 0 " xyz="0.0195 -0.0228 -0.022"/>
      <geometry>
        <box size="0.001 0.0405 0.026"/>
      </geometry>
    </visual>
    <inertial>
      <mass value="0"/>
      <origin rpy="0 0 0" xyz="0 0 0"/>
      <inertia ixx="0" ixy="0" ixz="0" iyy="0" iyz="0" izz="0"/>
    </inertial>
    <collision>
      <origin rpy="0 0 0 " xyz="0.0195 -0.0228 -0.022"/>
      <geometry>
        <box size="0.001 0.0405 0.026"/>
      </geometry>
    </collision>
  </link>
  <joint name="palm_sensor_2_joint" type="fixed">
    <parent link="allegro_base_link"/>
    <child link="palm_sensor_2_link"/>
    <origin xyz="0 0 0" rpy="0 0 0" />
  </joint>

  <!-- palm sensor 3 (bottom-left) -->
  <link name="palm_sensor_3_link">
    <visual>
      <origin rpy="0 0 0 " xyz="0.0195 -0.0228 -0.053"/>
      <geometry>
        <box size="0.001 0.0405 0.026"/>
      </geometry>
    </visual>
    <inertial>
      <mass value="0"/>
      <origin rpy="0 0 0" xyz="0 0 0"/>
      <inertia ixx="0" ixy="0" ixz="0" iyy="0" iyz="0" izz="0"/>
    </inertial>
    <collision>
      <origin rpy="0 0 0 " xyz="0.0195 -0.0228 -0.053"/>
      <geometry>
        <box size="0.001 0.0405 0.026"/>
      </geometry>
    </collision>
  </link>
  <joint name="palm_sensor_3_joint" type="fixed">
    <parent link="allegro_base_link"/>
    <child link="palm_sensor_3_link"/>
    <origin xyz="0 0 0" rpy="0 0 0" />
  </joint>


  <!--INDEX FINGER-->

  <link name="allegro_link_11">
    <visual>
     <origin rpy="1.57079632679  0 -1.57079632679 " xyz="0 0 -0.0005"/>
     <geometry>
       <mesh filename="package://xela_models/mesh_simplified/finger_link_1.obj" scale="0.001 0.001 0.001"/>
     </geometry>
     <material name="green"/>
    </visual>
    <inertial>
     <mass value="0.050"/>
     <origin rpy="0 0 0" xyz="-0.000811 0.000477 0.008113"/>
     <inertia ixx="2414.056e-09" ixy="-0.383e-09" ixz="77.216e-09" iyy="1101.930e-09" iyz="-9.204e-09" izz="1979.858e-09"/>
    </inertial>

    <!-- Collision geometry - copy from visual -->
    <collision>
      <origin rpy="1.57079632679  0 -1.57079632679 " xyz="0 0 -0.0005"/>
      <geometry>
        <mesh filename="package://xela_models/mesh_simplified/finger_link_1.obj" scale="0.001 0.001 0.001"/>
      </geometry>
    </collision>
  </link>

  <joint name="allegro_joint_11" type="revolute">
    <axis xyz="0 0 1"/>
    <limit effort="15" lower="-0.47" upper="0.47" velocity="7"/>
    <parent link="allegro_base_link"/>
    <child link="allegro_link_11"/>
    <origin xyz="0 0.043773 -0.002249" rpy="-0.0872665 0 0" />
    <dynamics damping="3" friction="10"/>
  </joint>

  <link name="allegro_link_12">
    <visual>
     <origin rpy="0 1.57079632679  0" xyz="0 0 0"/>
     <geometry>
       <mesh filename="package://xela_models/mesh_simplified/finger_link_2.obj" scale="0.001 0.001 0.001"/>
     </geometry>
     <material name="yellow"/>
    </visual>

    <inertial>
      <mass value="0.180"/>
      <origin rpy="0 0 0" xyz="-0.00356 0.000033 0.027011"/>
     <inertia ixx="33463.517e-09" ixy="-137.897e-09" ixz="-57.882e-09" iyy="37612.493e-09" iyz="-46.694e-09" izz="13497.383e-09"/>
    </inertial>

    <!-- Collision geometry - copy from visual -->
    <collision>
      <origin rpy="0 1.57079632679  0" xyz="0 0 0"/>
      <geometry>
        <mesh filename="package://xela_models/mesh_simplified/finger_link_2.obj" scale="0.001 0.001 0.001"/>
      </geometry>
    </collision>
  </link>

 <joint name="allegro_joint_12" type="revolute">
    <axis xyz="0 1 0"/>
    <limit effort="15" lower="-0.196" upper="1.61" velocity="7"/>
    <parent link="allegro_link_11"/>
    <child link="allegro_link_12"/>
    <origin xyz="0 0 0.0192" rpy="0 0 0" />
    <dynamics damping="3" friction="5"/>
  </joint>

  <!-- index finger sensor 4 -->
  <link name="index_sensor_4_link">
    <visual>
      <origin rpy="0 0 0 " xyz="0.015 0.0 0.0082"/>
      <geometry>
        <box size="0.001 0.018 0.0205"/>
      </geometry>
    </visual>
    <inertial>
      <mass value="0"/>
      <origin rpy="0 0 0" xyz="0 0 0"/>
      <inertia ixx="0" ixy="0" ixz="0" iyy="0" iyz="0" izz="0"/>
    </inertial>
    <collision>
      <origin rpy="0 0 0 " xyz="0.015 0.0 0.0082"/>
      <geometry>
        <box size="0.001 0.018 0.0205"/>
      </geometry>
    </collision>
  </link>
  <joint name="index_sensor_4_joint" type="fixed">
    <parent link="allegro_link_12"/>
    <child link="index_sensor_4_link"/>
    <origin xyz="0 0 0" rpy="0 0 0" />
  </joint>

  <!-- index finger sensor 3 -->
  <link name="index_sensor_3_link">
    <visual>
      <origin rpy="0 0 0 " xyz="0.015 0.0 0.0458"/>
      <geometry>
        <box size="0.001 0.018 0.0205"/>
      </geometry>
    </visual>
    <inertial>
      <mass value="0"/>
      <origin rpy="0 0 0" xyz="0 0 0"/>
      <inertia ixx="0" ixy="0" ixz="0" iyy="0" iyz="0" izz="0"/>
    </inertial>
    <collision>
      <origin rpy="0 0 0 " xyz="0.015 0.0 0.0458"/>
      <geometry>
        <box size="0.001 0.018 0.0205"/>
      </geometry>
    </collision>
  </link>
  <joint name="index_sensor_3_joint" type="fixed">
    <parent link="allegro_link_12"/>
    <child link="index_sensor_3_link"/>
    <origin xyz="0 0 0" rpy="0 0 0" />
  </joint>

  <link name="allegro_link_13">
    <visual>
     <origin rpy="0 -1.57079632679  0" xyz="0 0 0.0425"/>
     <geometry>
       <mesh filename="package://xela_models/mesh_simplified/finger_link_3.obj" scale="0.001 0.001 0.001"/>
     </geometry>
     <material name="orange"/>
    </visual>

    <inertial>
      <mass value="0.080"/>
      <origin rpy="0 0 0" xyz="-0.002973 0.000065 0.029809"/>
      <inertia ixx="9811.638e-09" ixy="-23.174e-09" ixz="497.074e-09" iyy="11210.635e-09" iyz="-42.915e-09" izz="7480.75e-09"/>
    </inertial>

    <!-- Collision geometry - copy from visual -->
    <collision>
      <origin rpy="0 -1.57079632679  0" xyz="0 0 0.0425"/>
      <geometry>
        <mesh filename="package://xela_models/mesh_simplified/finger_link_3.obj" scale="0.001 0.001 0.001"/>
      </geometry>
    </collision>
  </link>

  <joint name="allegro_joint_13" type="revolute">
    <axis xyz="0 1 0"/>
    <limit effort="15" lower="-0.174" upper="1.709" velocity="7"/>
    <parent link="allegro_link_12"/>
    <child link="allegro_link_13"/>
    <origin xyz="0 0 0.054" rpy="0 0 0" />
    <dynamics damping="8" friction="10"/>
  </joint>

  <!-- index finger sensor 2 -->
  <link name="index_sensor_2_link">
    <visual>
      <origin rpy="0 0 0 " xyz="0.015 0.0 0.0344"/>
      <geometry>
        <box size="0.001 0.018 0.0205"/>
      </geometry>
    </visual>
    <inertial>
      <mass value="0"/>
      <origin rpy="0 0 0" xyz="0 0 0"/>
      <inertia ixx="0" ixy="0" ixz="0" iyy="0" iyz="0" izz="0"/>
    </inertial>
    <collision>
      <origin rpy="0 0 0 " xyz="0.015 0.0 0.0344"/>
      <geometry>
        <box size="0.001 0.018 0.0205"/>
      </geometry>
    </collision>
  </link>
  <joint name="index_sensor_2_joint" type="fixed">
    <parent link="allegro_link_13"/>
    <child link="index_sensor_2_link"/>
    <origin xyz="0 0 0" rpy="0 0 0" />
  </joint>

  <link name="allegro_link_14">
    <visual>
     <origin rpy="1.57079632679 0 -1.57079632679" xyz="0 0 0.0154"/>
     <geometry>
       <mesh filename="package://xela_models/mesh_simplified/finger_link_4.obj" scale="0.001 0.001 0.001"/>
     </geometry>
     <material name="red"/>
    </visual>

    <inertial>
     <mass value="0.080"/>
     <origin rpy="0 0 0" xyz="-0.000809 -0.00003 0.033361"/>
     <inertia ixx="7780.076e-09" ixy="-1.409e-09" ixz="170.689e-09" iyy="7260.287e-09" iyz="18.558e-09" izz="3969.241e-09"/>
    </inertial>

    <!-- Collision geometry - copy from visual -->
    <collision>
      <origin rpy="1.57079632679 0 -1.57079632679" xyz="0 0 0.0154"/>
      <geometry>
        <mesh filename="package://xela_models/mesh_simplified/finger_link_4.obj" scale="0.001 0.001 0.001"/>
      </geometry>
    </collision>
  </link>

  <joint name="allegro_joint_14" type="revolute">
    <axis xyz="0 1 0"/>
    <limit effort="15" lower="-0.227" upper="1.618" velocity="7"/>
    <parent link="allegro_link_13"/>
    <child link="allegro_link_14"/>
    <origin xyz="0 0 0.0424" rpy="0 0 0" />
    <dynamics damping="10" friction="12"/>
  </joint>

  <link name="allegro_link_14_tip">
  </link>

  <joint name="allegro_joint_14_tip" type="fixed">
    <parent link="allegro_link_14"/>
    <child link="allegro_link_14_tip"/>
    <origin xyz="-0.012601 0 0.020745" rpy="0 0 0" />
    <!--origin xyz="0.013341 0 0.043834" rpy="0 0 0" /-->
  </joint>


  <!--MIDDLE FINGER-->

  <link name="allegro_link_21" >
    <visual>
     <origin rpy="1.57079632679  0 -1.57079632679 " xyz="0 0 -0.0005"/>
     <geometry>
       <mesh filename="package://xela_models/mesh_simplified/finger_link_1.obj" scale="0.001 0.001 0.001"/>
     </geometry>
     <material name="green"/>
    </visual>

    <inertial>
     <mass value="0.050"/>
     <origin rpy="0 0 0" xyz="-0.000811 0.000477 0.008113"/>
     <inertia ixx="2414.056e-09" ixy="-0.383e-09" ixz="77.216e-09" iyy="1101.930e-09" iyz="-9.204e-09" izz="1979.858e-09"/>
    </inertial>

    <!-- Collision geometry - copy from visual -->
    <collision>
      <origin rpy="1.57079632679  0 -1.57079632679 " xyz="0 0 -0.0005"/>
      <geometry>
        <mesh filename="package://xela_models/mesh_simplified/finger_link_1.obj" scale="0.001 0.001 0.001"/>
      </geometry>
    </collision>
  </link>

  <joint name="allegro_joint_21" type="revolute">
    <axis xyz="0 0 1"/>
    <limit effort="15" lower="-0.47" upper="0.47" velocity="7"/>
    <parent link="allegro_base_link"/>
    <child link="allegro_link_21"/>
    <origin xyz="0 0 0" rpy="0 0 0" />
    <dynamics damping="3" friction="10"/>
  </joint>
 
  <link name="allegro_link_22" >

    <visual>
     <origin rpy="0 1.57079632679  0" xyz="0 0 0"/>
     <geometry>
       <mesh filename="package://xela_models/mesh_simplified/finger_link_2.obj" scale="0.001 0.001 0.001"/>
     </geometry>
     <material name="yellow"/>
    </visual>

    <inertial>
     <mass value="0.180"/>
     <origin rpy="0 0 0" xyz="-0.00356 0.000033 0.027011"/>
     <inertia ixx="33463.517e-09" ixy="-137.897e-09" ixz="-57.882e-09" iyy="37612.493e-09" iyz="-46.694e-09" izz="13497.383e-09"/>
    </inertial>

    <!-- Collision geometry - copy from visual -->
    <collision>
      <origin rpy="0 1.57079632679  0" xyz="0 0 0"/>
      <geometry>
        <mesh filename="package://xela_models/mesh_simplified/finger_link_2.obj" scale="0.001 0.001 0.001"/>
      </geometry>
    </collision>
  </link>

  <joint name="allegro_joint_22" type="revolute">
    <axis xyz="0 1 0"/>
    <limit effort="15" lower="-0.196" upper="1.61" velocity="7"/>
    <parent link="allegro_link_21"/>
    <child link="allegro_link_22"/>
    <origin xyz="0 0 0.0192" rpy="0 0 0" />
    <dynamics damping="3" friction="5"/>
  </joint>

  <!-- middle finger sensor 4 -->
  <link name="middle_sensor_4_link">
    <visual>
      <origin rpy="0 0 0 " xyz="0.015 0.0 0.0082"/>
      <geometry>
        <box size="0.001 0.018 0.0205"/>
      </geometry>
    </visual>
    <inertial>
      <mass value="0"/>
      <origin rpy="0 0 0" xyz="0 0 0"/>
      <inertia ixx="0" ixy="0" ixz="0" iyy="0" iyz="0" izz="0"/>
    </inertial>
    <collision>
      <origin rpy="0 0 0 " xyz="0.015 0.0 0.0082"/>
      <geometry>
        <box size="0.001 0.018 0.0205"/>
      </geometry>
    </collision>
  </link>
  <joint name="middle_sensor_4_joint" type="fixed">
    <parent link="allegro_link_22"/>
    <child link="middle_sensor_4_link"/>
    <origin xyz="0 0 0" rpy="0 0 0" />
  </joint>

  <!-- middle finger sensor 3 -->
  <link name="middle_sensor_3_link">
    <visual>
      <origin rpy="0 0 0 " xyz="0.015 0.0 0.0458"/>
      <geometry>
        <box size="0.001 0.018 0.0205"/>
      </geometry>
    </visual>
    <inertial>
      <mass value="0"/>
      <origin rpy="0 0 0" xyz="0 0 0"/>
      <inertia ixx="0" ixy="0" ixz="0" iyy="0" iyz="0" izz="0"/>
    </inertial>
    <collision>
      <origin rpy="0 0 0 " xyz="0.015 0.0 0.0458"/>
      <geometry>
        <box size="0.001 0.018 0.0205"/>
      </geometry>
    </collision>
  </link>
  <joint name="middle_sensor_3_joint" type="fixed">
    <parent link="allegro_link_22"/>
    <child link="middle_sensor_3_link"/>
    <origin xyz="0 0 0" rpy="0 0 0" />
  </joint>
  
  <link name="allegro_link_23" >
    <visual>
     <origin rpy="0 -1.57079632679  0" xyz="0 0 0.0425"/>
     <geometry>
       <mesh filename="package://xela_models/mesh_simplified/finger_link_3.obj" scale="0.001 0.001 0.001"/>
     </geometry>
     <material name="orange"/>
    </visual>

    <inertial>
     <mass value="0.080"/>
     <origin rpy="0 0 0" xyz="-0.002973 0.000065 0.029809"/>
     <inertia ixx="9811.638e-09" ixy="-23.174e-09" ixz="497.074e-09" iyy="11210.635e-09" iyz="-42.915e-09" izz="7480.75e-09"/>
    </inertial>

    <!-- Collision geometry - copy from visual -->
    <collision>
      <origin rpy="0 -1.57079632679  0" xyz="0 0 0.0425"/>
      <geometry>
        <mesh filename="package://xela_models/mesh_simplified/finger_link_3.obj" scale="0.001 0.001 0.001"/>
      </geometry>
    </collision>
  </link>

  <joint name="allegro_joint_23" type="revolute">
    <axis xyz="0 1 0"/>
    <limit effort="15" lower="-0.174" upper="1.709" velocity="7"/>
    <parent link="allegro_link_22"/>
    <child link="allegro_link_23"/>
    <origin xyz="0 0 0.054" rpy="0 0 0" />
    <dynamics damping="8" friction="10"/>
  </joint>

  <!-- middle finger sensor 2 -->
  <link name="middle_sensor_2_link">
    <visual>
      <origin rpy="0 0 0 " xyz="0.015 0.0 0.0344"/>
      <geometry>
        <box size="0.001 0.018 0.0205"/>
      </geometry>
    </visual>
    <inertial>
      <mass value="0"/>
      <origin rpy="0 0 0" xyz="0 0 0"/>
      <inertia ixx="0" ixy="0" ixz="0" iyy="0" iyz="0" izz="0"/>
    </inertial>
    <collision>
      <origin rpy="0 0 0 " xyz="0.015 0.0 0.0344"/>
      <geometry>
        <box size="0.001 0.018 0.0205"/>
      </geometry>
    </collision>
  </link>
  <joint name="middle_sensor_2_joint" type="fixed">
    <parent link="allegro_link_23"/>
    <child link="middle_sensor_2_link"/>
    <origin xyz="0 0 0" rpy="0 0 0" />
  </joint>
  
  <link name="allegro_link_24" >

    <visual>
     <origin rpy="1.57079632679 0 -1.57079632679" xyz="0 0 0.0154"/>
     <geometry>
       <mesh filename="package://xela_models/mesh_simplified/finger_link_4.obj" scale="0.001 0.001 0.001"/>
     </geometry>
     <material name="red"/>
    </visual>

    <inertial>
     <mass value="0.080"/>
     <origin rpy="0 0 0" xyz="-0.000809 -0.00003 0.033361"/>
     <inertia ixx="7780.076e-09" ixy="-1.409e-09" ixz="170.689e-09" iyy="7260.287e-09" iyz="18.558e-09" izz="3969.241e-09"/>
    </inertial>

    <!-- Collision geometry - copy from visual -->
    <collision>
      <origin rpy="1.57079632679 0 -1.57079632679" xyz="0 0 0.0154"/>
      <geometry>
        <mesh filename="package://xela_models/mesh_simplified/finger_link_4.obj" scale="0.001 0.001 0.001"/>
      </geometry>
    </collision>

  </link>

  <joint name="allegro_joint_24" type="revolute">
    <axis xyz="0 1 0"/>
    <limit effort="15" lower="-0.227" upper="1.618" velocity="7"/>
    <parent link="allegro_link_23"/>
    <child link="allegro_link_24"/>
    <origin xyz="0 0 0.0424" rpy="0 0 0" />
    <dynamics damping="10" friction="12"/>
  </joint>

  <link name="allegro_link_24_tip">
  </link>

  <joint name="allegro_joint_24_tip" type="fixed">
    <parent link="allegro_link_24"/>
    <child link="allegro_link_24_tip"/>
    <origin xyz="-0.012601 0 0.020745" rpy="0 0 0" />
    <!--origin xyz="0.013341 0 0.043834" rpy="0 0 0" /-->
  </joint>


    <!--RING FINGER-->
  <link name="allegro_link_31" >

    <visual>
     <origin rpy="1.57079632679  0 -1.57079632679 " xyz="0 0 -0.0005"/>
     <geometry>
       <mesh filename="package://xela_models/mesh_simplified/finger_link_1.obj" scale="0.001 0.001 0.001"/>
     </geometry>
     <material name="green"/>
    </visual>

    <inertial>
     <mass value="0.050"/>
     <origin rpy="0 0 0" xyz="-0.000811 0.000477 0.008113"/>
     <inertia ixx="2414.056e-09" ixy="-0.383e-09" ixz="77.216e-09" iyy="1101.930e-09" iyz="-9.204e-09" izz="1979.858e-09"/>
    </inertial>

    <!-- Collision geometry - copy from visual -->
    <collision>
      <origin rpy="1.57079632679  0 -1.57079632679 " xyz="0 0 -0.0005"/>
      <geometry>
        <mesh filename="package://xela_models/mesh_simplified/finger_link_1.obj" scale="0.001 0.001 0.001"/>
      </geometry>
    </collision>

  </link>

  <joint name="allegro_joint_31" type="revolute">
    <axis xyz="0 0 1"/>
    <limit effort="15" lower="-0.47" upper="0.47" velocity="7"/>
    <parent link="allegro_base_link"/>
    <child link="allegro_link_31"/>
    <origin xyz="0 -0.043773 -0.002249" rpy="0.0872665 0 0" />
    <dynamics damping="3" friction="10"/>
  </joint>
  
  <link name="allegro_link_32" >

    <visual>
     <origin rpy="0 1.57079632679  0" xyz="0 0 0"/>
     <geometry>
       <mesh filename="package://xela_models/mesh_simplified/finger_link_2.obj" scale="0.001 0.001 0.001"/>
     </geometry>
     <material name="yellow"/>
    </visual>

    <inertial>
     <mass value="0.180"/>
     <origin rpy="0 0 0" xyz="-0.00356 0.000033 0.027011"/>
     <inertia ixx="33463.517e-09" ixy="-137.897e-09" ixz="-57.882e-09" iyy="37612.493e-09" iyz="-46.694e-09" izz="13497.383e-09"/>
    </inertial>

    <!-- Collision geometry - copy from visual -->
    <collision>
      <origin rpy="0 1.57079632679  0" xyz="0 0 0"/>
      <geometry>
        <mesh filename="package://xela_models/mesh_simplified/finger_link_2.obj" scale="0.001 0.001 0.001"/>
      </geometry>
    </collision>
  </link>

  <joint name="allegro_joint_32" type="revolute">
    <axis xyz="0 1 0"/>
    <limit effort="15" lower="-0.196" upper="1.61" velocity="7"/>
    <parent link="allegro_link_31"/>
    <child link="allegro_link_32"/>
    <origin xyz="0 0 0.0192" rpy="0 0 0" />
    <dynamics damping="3" friction="5"/>
  </joint>

  <!-- ring finger sensor 4 -->
  <link name="ring_sensor_4_link">
    <visual>
      <origin rpy="0 0 0 " xyz="0.015 0.0 0.0082"/>
      <geometry>
        <box size="0.001 0.018 0.0205"/>
      </geometry>
    </visual>
    <inertial>
      <mass value="0"/>
      <origin rpy="0 0 0" xyz="0 0 0"/>
      <inertia ixx="0" ixy="0" ixz="0" iyy="0" iyz="0" izz="0"/>
    </inertial>
    <collision>
      <origin rpy="0 0 0 " xyz="0.015 0.0 0.0082"/>
      <geometry>
        <box size="0.001 0.018 0.0205"/>
      </geometry>
    </collision>
  </link>
  <joint name="ring_sensor_4_joint" type="fixed">
    <parent link="allegro_link_32"/>
    <child link="ring_sensor_4_link"/>
    <origin xyz="0 0 0" rpy="0 0 0" />
  </joint>

  <!-- ring finger sensor 3 -->
  <link name="ring_sensor_3_link">
    <visual>
      <origin rpy="0 0 0 " xyz="0.015 0.0 0.0458"/>
      <geometry>
        <box size="0.001 0.018 0.0205"/>
      </geometry>
    </visual>
    <inertial>
      <mass value="0"/>
      <origin rpy="0 0 0" xyz="0 0 0"/>
      <inertia ixx="0" ixy="0" ixz="0" iyy="0" iyz="0" izz="0"/>
    </inertial>
    <collision>
      <origin rpy="0 0 0 " xyz="0.015 0.0 0.0458"/>
      <geometry>
        <box size="0.001 0.018 0.0205"/>
      </geometry>
    </collision>
  </link>
  <joint name="ring_sensor_3_joint" type="fixed">
    <parent link="allegro_link_32"/>
    <child link="ring_sensor_3_link"/>
    <origin xyz="0 0 0" rpy="0 0 0" />
  </joint>
 
  <link name="allegro_link_33">

    <visual>
     <origin rpy="0 -1.57079632679  0" xyz="0 0 0.0425"/>
     <geometry>
       <mesh filename="package://xela_models/mesh_simplified/finger_link_3.obj" scale="0.001 0.001 0.001"/>
     </geometry>
     <material name="orange"/>
    </visual>

    <inertial>
     <mass value="0.080"/>
     <origin rpy="0 0 0" xyz="-0.002973 0.000065 0.029809"/>
     <inertia ixx="9811.638e-09" ixy="-23.174e-09" ixz="497.074e-09" iyy="11210.635e-09" iyz="-42.915e-09" izz="7480.75e-09"/>
    </inertial>

    <!-- Collision geometry - copy from visual -->
    <collision>
      <origin rpy="0 -1.57079632679  0" xyz="0 0 0.0425"/>
      <geometry>
        <mesh filename="package://xela_models/mesh_simplified/finger_link_3.obj" scale="0.001 0.001 0.001"/>
      </geometry>
    </collision>

  </link>

 <joint name="allegro_joint_33" type="revolute">
    <axis xyz="0 1 0"/>
    <limit effort="15" lower="-0.174" upper="1.709" velocity="7"/>
    <parent link="allegro_link_32"/>
    <child link="allegro_link_33"/>
    <origin xyz="0 0 0.054" rpy="0 0 0" />
    <dynamics damping="8" friction="10"/>
  </joint>

  <!-- ring finger sensor 2 -->
  <link name="ring_sensor_2_link">
    <visual>
      <origin rpy="0 0 0 " xyz="0.015 0.0 0.0344"/>
      <geometry>
        <box size="0.001 0.018 0.0205"/>
      </geometry>
    </visual>
    <inertial>
      <mass value="0"/>
      <origin rpy="0 0 0" xyz="0 0 0"/>
      <inertia ixx="0" ixy="0" ixz="0" iyy="0" iyz="0" izz="0"/>
    </inertial>
    <collision>
      <origin rpy="0 0 0 " xyz="0.015 0.0 0.0344"/>
      <geometry>
        <box size="0.001 0.018 0.0205"/>
      </geometry>
    </collision>
  </link>
  <joint name="ring_sensor_2_joint" type="fixed">
    <parent link="allegro_link_33"/>
    <child link="ring_sensor_2_link"/>
    <origin xyz="0 0 0" rpy="0 0 0" />
  </joint>
  
  <link name="allegro_link_34" >

    <visual>
     <origin rpy="1.57079632679 0 -1.57079632679" xyz="0 0 0.0154"/>
     <geometry>
       <mesh filename="package://xela_models/mesh_simplified/finger_link_4.obj" scale="0.001 0.001 0.001"/>
     </geometry>
    <material name="red"/>
    </visual>

    <inertial>
     <mass value="0.080"/>
     <origin rpy="0 0 0" xyz="-0.000809 -0.00003 0.033361"/>
     <inertia ixx="7780.076e-09" ixy="-1.409e-09" ixz="170.689e-09" iyy="7260.287e-09" iyz="18.558e-09" izz="3969.241e-09"/>
    </inertial>

    <!-- Collision geometry - copy from visual -->
    <collision>
      <origin rpy="1.57079632679 0 -1.57079632679" xyz="0 0 0.0154"/>
      <geometry>
        <mesh filename="package://xela_models/mesh_simplified/finger_link_4.obj" scale="0.001 0.001 0.001"/>
      </geometry>
    </collision>

  </link>

  <joint name="allegro_joint_34" type="revolute">
    <axis xyz="0 1 0"/>
    <limit effort="15" lower="-0.227" upper="1.618" velocity="7"/>
    <parent link="allegro_link_33"/>
    <child link="allegro_link_34"/>
    <origin xyz="0 0 0.0424" rpy="0 0 0" />
    <dynamics damping="10" friction="12"/>
  </joint>

  <link name="allegro_link_34_tip">
  </link>

  <joint name="allegro_joint_34_tip" type="fixed">
    <parent link="allegro_link_34"/>
    <child link="allegro_link_34_tip"/>
    <origin xyz="-0.012601 0 0.020745" rpy="0 0 0" />
    <!--origin xyz="0.013341 0 0.043834" rpy="0 0 0" /-->
  </joint>


   <!--THUMB-->
  <link name="allegro_link_41" >

    <visual>
     <origin rpy="3.14159265359 0 -1.57079632679" xyz="0.0446 0 0"/>
     <geometry>
       <mesh filename="package://xela_models/mesh_simplified/thumb_link_1.obj" scale="0.001 0.001 0.001"/>
     </geometry>
     <material name="green"/>
    </visual>

    <inertial>
     <mass value="0.0680"/>
     <origin rpy="0 0 0" xyz="0.009297 0.008825 0.015128"/>
     <inertia ixx="14941.462e-09" ixy="674.976e-09" ixz="-305.859e-09" iyy="18499.069e-09" iyz="1170.808e-09" izz="14309.75e-09"/>
    </inertial>

    <!-- Collision geometry - copy from visual -->
    <collision>
      <origin rpy="3.14159265359 0 -1.57079632679" xyz="0.0446 0 0"/>
      <geometry>
        <mesh filename="package://xela_models/mesh_simplified/thumb_link_1.obj" scale="0.001 0.001 0.001"/>
      </geometry>
    </collision>

  </link>

  <joint name="allegro_joint_41" type="revolute">
    <axis xyz="-1 0 0"/>
    <limit effort="15" lower="0.25" upper="1.6" velocity="7"/>
    <parent link="allegro_base_link"/>
    <child link="allegro_link_41"/>
    <origin xyz="-0.0182 0.016958 -0.073288" rpy="-3.14159 -1.48353 1.5708" />
    <dynamics damping="3" friction="10"/>
  </joint>

  <link name="allegro_link_42" >
    <visual>
     <origin rpy="1.57079632679 0 -1.57079632679" xyz="0 0 -0.0005"/>
     <geometry>
       <mesh filename="package://xela_models/mesh_simplified/thumb_link_2.obj" scale="0.001 0.001 0.001"/>
     </geometry>
     <material name="yellow"/>
    </visual>

    <inertial>
     <mass value="0.015"/>
     <origin rpy="0 0 0" xyz="-0.000477 0.008113 0.000811"/>
     <inertia ixx="1101.930e-09" ixy="0.383e-09" ixz="9.204e-09" iyy="2414.056e-09" iyz="77.216e-09" izz="1979.858e-09"/>
    </inertial>

    <!-- Collision geometry - copy from visual -->
    <collision>
      <origin rpy="1.57079632679 0 -1.57079632679" xyz="0 0 -0.0005"/>
      <geometry>
        <mesh filename="package://xela_models/mesh_simplified/thumb_link_2.obj" scale="0.001 0.001 0.001"/>
      </geometry>
    </collision>

  </link> 

  <joint name="allegro_joint_42" type="revolute">
    <axis xyz="0 0 1"/>
    <limit effort="15" lower="-0.105" upper="1.163" velocity="7"/>
    <parent link="allegro_link_41"/>
    <child link="allegro_link_42"/>
    <origin xyz="0 0.005 0.0402" rpy="0 0 0" />
    <dynamics damping="3" friction="5"/>
  </joint>
  
  <link name="allegro_link_43" >
  <visual>
     <origin rpy="-1.57079632679 1.57079632679 -1.57079632679" xyz="0 0 0"/>
     <geometry>
       <mesh filename="package://xela_models/mesh_simplified/thumb_link_3.obj" scale="0.001 0.001 0.001"/>
     </geometry>
     <material name="orange"/>
    </visual>

    <inertial>
     <mass value="0.095"/>
     <origin rpy="0 0 0" xyz="-0.003196 0.000188 0.013453"/>
     <inertia ixx="12096.373e-09" ixy="-17.650e-09" ixz="-979.939e-09" iyy="13369.697e-09" iyz="-80.073e-09" izz="7544.397e-09"/>
    </inertial>

    <!-- Collision geometry - copy from visual -->
    <collision>
      <origin rpy="-1.57079632679 1.57079632679 -1.57079632679" xyz="0 0 0"/>
      <geometry>
        <mesh filename="package://xela_models/mesh_simplified/thumb_link_3.obj" scale="0.001 0.001 0.001"/>
      </geometry>
    </collision>
  </link> 

  <joint name="allegro_joint_43" type="revolute">
    <axis xyz="0 1 0"/>
    <limit effort="15" lower="-0.189" upper="1.644" velocity="7"/>
    <parent link="allegro_link_42"/>
    <child link="allegro_link_43"/>
    <origin xyz="0 0 0.0192" rpy="0 0 0" />
    <dynamics damping="3" friction="10"/>
  </joint>

  <!-- thumb finger sensor 3 -->
  <link name="thumb_sensor_3_link">
    <visual>
      <origin rpy="0 0 0 " xyz="0.015 0.0 0.01"/>
      <geometry>
        <box size="0.001 0.018 0.0205"/>
      </geometry>
    </visual>
    <inertial>
      <mass value="0"/>
      <origin rpy="0 0 0" xyz="0 0 0"/>
      <inertia ixx="0" ixy="0" ixz="0" iyy="0" iyz="0" izz="0"/>
    </inertial>
    <collision>
      <origin rpy="0 0 0 " xyz="0.015 0.0 0.01"/>
      <geometry>
        <box size="0.001 0.018 0.0205"/>
      </geometry>
    </collision>
  </link>
  <joint name="thumb_sensor_3_joint" type="fixed">
    <parent link="allegro_link_43"/>
    <child link="thumb_sensor_3_link"/>
    <origin xyz="0 0 0" rpy="0 0 0" />
  </joint>
  
  <link name="allegro_link_44" >

  <visual>
     <origin rpy="-1.57079632679 1.57079632679 -1.57079632679" xyz="0 0 0"/>
     <geometry>
       <mesh filename="package://xela_models/mesh_simplified/thumb_link_4.obj" scale="0.001 0.001 0.001"/>
     </geometry>
     <material name="red"/>
    </visual>

    <inertial>
     <mass value="0.110"/>
     <origin rpy="0 0 0" xyz="0.00005 -0.001611 0.035166"/>
     <inertia ixx="33947.965e-09" ixy="-0.538e-09" ixz="-142.573e-09" iyy="33136.228e-09" iyz="-1585.247e-09" izz="8796.735e-09"/>
    </inertial>

    <!-- Collision geometry - copy from visual -->
    <collision>
      <origin rpy="-1.57079632679 1.57079632679 -1.57079632679" xyz="0 0 0"/>
      <geometry>
        <mesh filename="package://xela_models/mesh_simplified/thumb_link_4.obj" scale="0.001 0.001 0.001"/>
      </geometry>
    </collision>
  </link> 
  
  <joint name="allegro_joint_44" type="revolute">
    <axis xyz="0 1 0"/>
    <limit effort="15" lower="-0.162" upper="1.719" velocity="7"/>
    <parent link="allegro_link_43"/>
    <child link="allegro_link_44"/>
    <origin xyz="0 0 0.0514" rpy="0 0 0" />
    <dynamics damping="3" friction="12"/>
  </joint>

  <!-- thumb finger sensor 2 -->
  <link name="thumb_sensor_2_link">
    <visual>
      <origin rpy="0 0 0 " xyz="0.015 0.0 0.0082"/>
      <geometry>
        <box size="0.001 0.018 0.0205"/>
      </geometry>
    </visual>
    <inertial>
      <mass value="0"/>
      <origin rpy="0 0 0" xyz="0 0 0"/>
      <inertia ixx="0" ixy="0" ixz="0" iyy="0" iyz="0" izz="0"/>
    </inertial>
    <collision>
      <origin rpy="0 0 0 " xyz="0.015 0.0 0.0082"/>
      <geometry>
        <box size="0.001 0.018 0.0205"/>
      </geometry>
    </collision>
  </link>
  <joint name="thumb_sensor_2_joint" type="fixed">
    <parent link="allegro_link_44"/>
    <child link="thumb_sensor_2_link"/>
    <origin xyz="0 0 0" rpy="0 0 0" />
  </joint>
  
  <link name="allegro_link_44_tip">
  </link>
  <joint name="allegro_joint_44_tip" type="fixed">
    <parent link="allegro_link_44"/>
    <child link="allegro_link_44_tip"/>
    <origin xyz="-0.01392 -0.0001 0.0313" rpy="0 0 0" />
    <!--origin xyz="0.013474 0 0.055469" rpy="0 0 0" /-->
  </joint>
</robot>
 
